Workbook

Sheet Blaze Calculations
G1: Note | H1: (Loreley V2 change Embers into 45% damage dealt, not just burn. I still don't know what Loreley V6 changes)
H2: (Lewis V6 does more volleys if the toy holder have extra action, look at the table on the right for more info)
Q3: Units | R3: EA
B4: For Different Duplicates, change the Yellow listed cells | Q4: Tololo | R4: +2 | S4: w Springfield V1
B5: =IF(C8="V6","V6 Lewis Volley Fire/Round","") -> V6 Lewis Volley Fire/Round | E5: =2+IF(C8="V6",INDEX('Lewis Conf. Index'!$C$26:$C$31,MATCH('Blaze Calculations'!$G$5,'Lewis Conf. Index'!B26:B31,0))+INDEX('Lewis Conf. Index'!$C$26:$C$31,MATCH('Blaze Calculations'!$I$5,'Lewis Conf. Index'!B26:B31,0)),"") -> 3 | F5: =IF(C8="V6","Toy holder 1","") -> Toy holder 1 | G5: +1 Extra Action | H5: =IF(C8="V6","Toy holder 2","") -> Toy holder 2 | I5: No Extra Action | J5: =IF(C8="V6","Change green cells for different toy holders","") -> Change green cells for different toy holders | Q5: Loreley V2 | R5: +1
Q6: Niketta V1 | R6: +1
A7: Turns | B7: Skill | C7: Lewis | D7: Skill | E7: Sakura | F7: Skill | G7: Loreley | H7: Skill | I7: Ots-14 Burn | J7: Blaze Stacks Per Turn | K7: Blaze Stacks Accumulated | L7: Ember Count | M7: Ember Uptime | N7: +1 extra action per round | O7: Crit Dmg Increase | Q7: Soppo V1 | R7: +1
C8: V6 | E8: - | G8: V2 | I8: - | Q8: Liushih | R8: +1
A9: Round 1 | B9: =_xlfn.IFS($C$8='Blaze Stacking Data'!$F$9,'Blaze Stacking Data'!F10,$C$8='Blaze Stacking Data'!$F$19,'Blaze Stacking Data'!F20,$C$8='Blaze Stacking Data'!$F$41,'Blaze Stacking Data'!F42,$C$8="-","") -> S2 | C9: =_xlfn.IFS($C$8='Blaze Stacking Data'!$F$9,'Blaze Stacking Data'!G10,$C$8='Blaze Stacking Data'!$F$19,'Blaze Stacking Data'!G20,$C$8='Blaze Stacking Data'!$F$41,'Blaze Stacking Data'!G42,$C$8="-","0") -> 6 | D9: =_xlfn.IFS($E$8='Blaze Stacking Data'!$H$9,'Blaze Stacking Data'!H10,$E$8='Blaze Stacking Data'!$H$19,'Blaze Stacking Data'!H20,$E$8='Blaze Stacking Data'!$H$30,'Blaze Stacking Data'!H31,$E$8='Blaze Stacking Data'!$H$41,'Blaze Stacking Data'!H42,$E$8="-","") | E9: =_xlfn.IFS($E$8='Blaze Stacking Data'!$H$9,'Blaze Stacking Data'!I10,$E$8='Blaze Stacking Data'!$H$19,'Blaze Stacking Data'!I20,$E$8='Blaze Stacking Data'!$H$30,'Blaze Stacking Data'!I31,$E$8='Blaze Stacking Data'!$H$41,'Blaze Stacking Data'!I42,$E$8="-","0") -> 0 | F9: =_xlfn.IFS($G$8='Blaze Stacking Data'!$J$9,'Blaze Stacking Data'!J10,$G$8='Blaze Stacking Data'!$J$19,'Blaze Stacking Data'!J20,$G$8='Blaze Stacking Data'!$J$30,'Blaze Stacking Data'!J31,$G$8='Blaze Stacking Data'!$J$41,'Blaze Stacking Data'!J42,$G$8="-","") -> S3+S2 | G9: =_xlfn.IFS($G$8='Blaze Stacking Data'!$J$9,'Blaze Stacking Data'!K10,$G$8='Blaze Stacking Data'!$J$19,'Blaze Stacking Data'!K20,$G$8='Blaze Stacking Data'!$J$30,'Blaze Stacking Data'!K31,$G$8='Blaze Stacking Data'!$J$41,'Blaze Stacking Data'!K42,$G$8="-","0") -> 30 | H9: =_xlfn.IFS($I$8='Blaze Stacking Data'!$J$9,'Blaze Stacking Data'!L10,$I$8='Blaze Stacking Data'!$J$19,'Blaze Stacking Data'!L20,$I$8='Blaze Stacking Data'!$J$30,'Blaze Stacking Data'!L31,$I$8='Blaze Stacking Data'!$J$41,'Blaze Stacking Data'!L42,$I$8="-","") | I9: =_xlfn.IFS($I$8='Blaze Stacking Data'!$J$9,'Blaze Stacking Data'!M10,$I$8='Blaze Stacking Data'!$J$19,'Blaze Stacking Data'!M20,$I$8='Blaze Stacking Data'!$J$30,'Blaze Stacking Data'!M31,$I$8='Blaze Stacking Data'!$J$41,'Blaze Stacking Data'!M42,$I$8="-","0") -> 0 | J9: =SUM(G9+E9+C9+I9) -> 36 | K9: =J9 -> 36 | L9: =ROUNDDOWN(K9/35,0) -> 1 | M9: =IF(L9>0,"Yes","No") -> Yes | N9: =IF(L9=1,"Yes","No") -> Yes | O9: =L9*5% -> 0.05
A10: Round 2 | B10: =_xlfn.IFS($C$8='Blaze Stacking Data'!$F$9,'Blaze Stacking Data'!F11,$C$8='Blaze Stacking Data'!$F$19,'Blaze Stacking Data'!F21,$C$8='Blaze Stacking Data'!$F$41,'Blaze Stacking Data'!F43,$C$8="-","") -> S3 | C10: =_xlfn.IFS($C$8='Blaze Stacking Data'!$F$9,'Blaze Stacking Data'!G11,$C$8='Blaze Stacking Data'!$F$19,'Blaze Stacking Data'!G21,$C$8='Blaze Stacking Data'!$F$41,'Blaze Stacking Data'!G43,$C$8="-","0") -> 21 | D10: =_xlfn.IFS($E$8='Blaze Stacking Data'!$H$9,'Blaze Stacking Data'!H11,$E$8='Blaze Stacking Data'!$H$19,'Blaze Stacking Data'!H21,$E$8='Blaze Stacking Data'!$H$30,'Blaze Stacking Data'!H32,$E$8='Blaze Stacking Data'!$H$41,'Blaze Stacking Data'!H43,$E$8="-","") | E10: =_xlfn.IFS($E$8='Blaze Stacking Data'!$H$9,'Blaze Stacking Data'!I11,$E$8='Blaze Stacking Data'!$H$19,'Blaze Stacking Data'!I21,$E$8='Blaze Stacking Data'!$H$30,'Blaze Stacking Data'!I32,$E$8='Blaze Stacking Data'!$H$41,'Blaze Stacking Data'!I43,$E$8="-","0") -> 0 | F10: =_xlfn.IFS($G$8='Blaze Stacking Data'!$J$9,'Blaze Stacking Data'!J11,$G$8='Blaze Stacking Data'!$J$19,'Blaze Stacking Data'!J21,$G$8='Blaze Stacking Data'!$J$30,'Blaze Stacking Data'!J32,$G$8='Blaze Stacking Data'!$J$41,'Blaze Stacking Data'!J43,$G$8="-","") -> S2+S1 | G10: =_xlfn.IFS($G$8='Blaze Stacking Data'!$J$9,'Blaze Stacking Data'!K11,$G$8='Blaze Stacking Data'!$J$19,'Blaze Stacking Data'!K21,$G$8='Blaze Stacking Data'!$J$30,'Blaze Stacking Data'!K32,$G$8='Blaze Stacking Data'!$J$41,'Blaze Stacking Data'!K43,$G$8="-","0") -> 12 | H10: =_xlfn.IFS($I$8='Blaze Stacking Data'!$J$9,'Blaze Stacking Data'!L11,$I$8='Blaze Stacking Data'!$J$19,'Blaze Stacking Data'!L21,$I$8='Blaze Stacking Data'!$J$30,'Blaze Stacking Data'!L32,$I$8='Blaze Stacking Data'!$J$41,'Blaze Stacking Data'!L43,$I$8="-","") | I10: =_xlfn.IFS($I$8='Blaze Stacking Data'!$J$9,'Blaze Stacking Data'!M11,$I$8='Blaze Stacking Data'!$J$19,'Blaze Stacking Data'!M21,$I$8='Blaze Stacking Data'!$J$30,'Blaze Stacking Data'!M32,$I$8='Blaze Stacking Data'!$J$41,'Blaze Stacking Data'!M43,$I$8="-","0") -> 0 | J10: =SUM(G10+E10+C10+I10) -> 33 | K10: =K9+J10 -> 69 | L10: =ROUNDDOWN(K10/35,0) -> 1 | M10: =IF(L10>0,"Yes","No") -> Yes | N10: =IF(L10=L9,"No",IF(L10<>L9,"Yes")) -> No | O10: =L10*5% -> 0.05
A11: Round 3 | B11: =_xlfn.IFS($C$8='Blaze Stacking Data'!$F$9,'Blaze Stacking Data'!F12,$C$8='Blaze Stacking Data'!$F$19,'Blaze Stacking Data'!F22,$C$8='Blaze Stacking Data'!$F$41,'Blaze Stacking Data'!F44,$C$8="-","") -> S2 | C11: =_xlfn.IFS($C$8='Blaze Stacking Data'!$F$9,'Blaze Stacking Data'!G12,$C$8='Blaze Stacking Data'!$F$19,'Blaze Stacking Data'!G22,$C$8='Blaze Stacking Data'!$F$41,'Blaze Stacking Data'!G44,$C$8="-","0") -> 15 | D11: =_xlfn.IFS($E$8='Blaze Stacking Data'!$H$9,'Blaze Stacking Data'!H12,$E$8='Blaze Stacking Data'!$H$19,'Blaze Stacking Data'!H22,$E$8='Blaze Stacking Data'!$H$30,'Blaze Stacking Data'!H33,$E$8='Blaze Stacking Data'!$H$41,'Blaze Stacking Data'!H44,$E$8="-","") | E11: =_xlfn.IFS($E$8='Blaze Stacking Data'!$H$9,'Blaze Stacking Data'!I12,$E$8='Blaze Stacking Data'!$H$19,'Blaze Stacking Data'!I22,$E$8='Blaze Stacking Data'!$H$30,'Blaze Stacking Data'!I33,$E$8='Blaze Stacking Data'!$H$41,'Blaze Stacking Data'!I44,$E$8="-","0") -> 0 | F11: =_xlfn.IFS($G$8='Blaze Stacking Data'!$J$9,'Blaze Stacking Data'!J12,$G$8='Blaze Stacking Data'!$J$19,'Blaze Stacking Data'!J22,$G$8='Blaze Stacking Data'!$J$30,'Blaze Stacking Data'!J33,$G$8='Blaze Stacking Data'!$J$41,'Blaze Stacking Data'!J44,$G$8="-","") -> S2+S1 | G11: =_xlfn.IFS($G$8='Blaze Stacking Data'!$J$9,'Blaze Stacking Data'!K12,$G$8='Blaze Stacking Data'!$J$19,'Blaze Stacking Data'!K22,$G$8='Blaze Stacking Data'!$J$30,'Blaze Stacking Data'!K33,$G$8='Blaze Stacking Data'!$J$41,'Blaze Stacking Data'!K44,$G$8="-","0") -> 12 | H11: =_xlfn.IFS($I$8='Blaze Stacking Data'!$J$9,'Blaze Stacking Data'!L12,$I$8='Blaze Stacking Data'!$J$19,'Blaze Stacking Data'!L22,$I$8='Blaze Stacking Data'!$J$30,'Blaze Stacking Data'!L33,$I$8='Blaze Stacking Data'!$J$41,'Blaze Stacking Data'!L44,$I$8="-","") | I11: =_xlfn.IFS($I$8='Blaze Stacking Data'!$J$9,'Blaze Stacking Data'!M12,$I$8='Blaze Stacking Data'!$J$19,'Blaze Stacking Data'!M22,$I$8='Blaze Stacking Data'!$J$30,'Blaze Stacking Data'!M33,$I$8='Blaze Stacking Data'!$J$41,'Blaze Stacking Data'!M44,$I$8="-","0") -> 0 | J11: =SUM(G11+E11+C11+I11) -> 27 | K11: =K10+J11 -> 96 | L11: =ROUNDDOWN(K11/35,0) -> 2 | M11: =IF(OR(L11=0,L9=L11),"No","Yes") -> Yes | N11: =IF(L11=L10,"No",IF(L11<>L10,"Yes")) -> Yes | O11: =L11*5% -> 0.1
A12: Round 4 | B12: =_xlfn.IFS($C$8='Blaze Stacking Data'!$F$9,'Blaze Stacking Data'!F13,$C$8='Blaze Stacking Data'!$F$19,'Blaze Stacking Data'!F23,$C$8='Blaze Stacking Data'!$F$41,'Blaze Stacking Data'!F45,$C$8="-","") -> S3 | C12: =_xlfn.IFS($C$8='Blaze Stacking Data'!$F$9,'Blaze Stacking Data'!G13,$C$8='Blaze Stacking Data'!$F$19,'Blaze Stacking Data'!G23,$C$8='Blaze Stacking Data'!$F$41,'Blaze Stacking Data'!G45,$C$8="-","0") -> 21 | D12: =_xlfn.IFS($E$8='Blaze Stacking Data'!$H$9,'Blaze Stacking Data'!H13,$E$8='Blaze Stacking Data'!$H$19,'Blaze Stacking Data'!H23,$E$8='Blaze Stacking Data'!$H$30,'Blaze Stacking Data'!H34,$E$8='Blaze Stacking Data'!$H$41,'Blaze Stacking Data'!H45,$E$8="-","") | E12: =_xlfn.IFS($E$8='Blaze Stacking Data'!$H$9,'Blaze Stacking Data'!I13,$E$8='Blaze Stacking Data'!$H$19,'Blaze Stacking Data'!I23,$E$8='Blaze Stacking Data'!$H$30,'Blaze Stacking Data'!I34,$E$8='Blaze Stacking Data'!$H$41,'Blaze Stacking Data'!I45,$E$8="-","0") -> 0 | F12: =_xlfn.IFS($G$8='Blaze Stacking Data'!$J$9,'Blaze Stacking Data'!J13,$G$8='Blaze Stacking Data'!$J$19,'Blaze Stacking Data'!J23,$G$8='Blaze Stacking Data'!$J$30,'Blaze Stacking Data'!J34,$G$8='Blaze Stacking Data'!$J$41,'Blaze Stacking Data'!J45,$G$8="-","") -> S3+S2 | G12: =_xlfn.IFS($G$8='Blaze Stacking Data'!$J$9,'Blaze Stacking Data'!K13,$G$8='Blaze Stacking Data'!$J$19,'Blaze Stacking Data'!K23,$G$8='Blaze Stacking Data'!$J$30,'Blaze Stacking Data'!K34,$G$8='Blaze Stacking Data'!$J$41,'Blaze Stacking Data'!K45,$G$8="-","0") -> 20 | H12: =_xlfn.IFS($I$8='Blaze Stacking Data'!$J$9,'Blaze Stacking Data'!L13,$I$8='Blaze Stacking Data'!$J$19,'Blaze Stacking Data'!L23,$I$8='Blaze Stacking Data'!$J$30,'Blaze Stacking Data'!L34,$I$8='Blaze Stacking Data'!$J$41,'Blaze Stacking Data'!L45,$I$8="-","") | I12: =_xlfn.IFS($I$8='Blaze Stacking Data'!$J$9,'Blaze Stacking Data'!M13,$I$8='Blaze Stacking Data'!$J$19,'Blaze Stacking Data'!M23,$I$8='Blaze Stacking Data'!$J$30,'Blaze Stacking Data'!M34,$I$8='Blaze Stacking Data'!$J$41,'Blaze Stacking Data'!M45,$I$8="-","0") -> 0 | J12: =SUM(G12+E12+C12+I12) -> 41 | K12: =K11+J12 -> 137 | L12: =ROUNDDOWN(K12/35,0) -> 3 | M12: =IF(OR(L12=0,L10=L12),"No","Yes") -> Yes | N12: =IF(L12=L11,"No",IF(L12<>L11,"Yes")) -> Yes | O12: =L12*5% -> 0.15
A13: Round 5 | B13: =_xlfn.IFS($C$8='Blaze Stacking Data'!$F$9,'Blaze Stacking Data'!F14,$C$8='Blaze Stacking Data'!$F$19,'Blaze Stacking Data'!F24,$C$8='Blaze Stacking Data'!$F$41,'Blaze Stacking Data'!F46,$C$8="-","") -> S2 | C13: =_xlfn.IFS($C$8='Blaze Stacking Data'!$F$9,'Blaze Stacking Data'!G14,$C$8='Blaze Stacking Data'!$F$19,'Blaze Stacking Data'!G24,$C$8='Blaze Stacking Data'!$F$41,'Blaze Stacking Data'!G46,$C$8="-","0") -> 15 | D13: =_xlfn.IFS($E$8='Blaze Stacking Data'!$H$9,'Blaze Stacking Data'!H14,$E$8='Blaze Stacking Data'!$H$19,'Blaze Stacking Data'!H24,$E$8='Blaze Stacking Data'!$H$30,'Blaze Stacking Data'!H35,$E$8='Blaze Stacking Data'!$H$41,'Blaze Stacking Data'!H46,$E$8="-","") | E13: =_xlfn.IFS($E$8='Blaze Stacking Data'!$H$9,'Blaze Stacking Data'!I14,$E$8='Blaze Stacking Data'!$H$19,'Blaze Stacking Data'!I24,$E$8='Blaze Stacking Data'!$H$30,'Blaze Stacking Data'!I35,$E$8='Blaze Stacking Data'!$H$41,'Blaze Stacking Data'!I46,$E$8="-","0") -> 0 | F13: =_xlfn.IFS($G$8='Blaze Stacking Data'!$J$9,'Blaze Stacking Data'!J14,$G$8='Blaze Stacking Data'!$J$19,'Blaze Stacking Data'!J24,$G$8='Blaze Stacking Data'!$J$30,'Blaze Stacking Data'!J35,$G$8='Blaze Stacking Data'!$J$41,'Blaze Stacking Data'!J46,$G$8="-","") -> S2+S1 | G13: =_xlfn.IFS($G$8='Blaze Stacking Data'!$J$9,'Blaze Stacking Data'!K14,$G$8='Blaze Stacking Data'!$J$19,'Blaze Stacking Data'!K24,$G$8='Blaze Stacking Data'!$J$30,'Blaze Stacking Data'!K35,$G$8='Blaze Stacking Data'!$J$41,'Blaze Stacking Data'!K46,$G$8="-","0") -> 12 | H13: =_xlfn.IFS($I$8='Blaze Stacking Data'!$J$9,'Blaze Stacking Data'!L14,$I$8='Blaze Stacking Data'!$J$19,'Blaze Stacking Data'!L24,$I$8='Blaze Stacking Data'!$J$30,'Blaze Stacking Data'!L35,$I$8='Blaze Stacking Data'!$J$41,'Blaze Stacking Data'!L46,$I$8="-","") | I13: =_xlfn.IFS($I$8='Blaze Stacking Data'!$J$9,'Blaze Stacking Data'!M14,$I$8='Blaze Stacking Data'!$J$19,'Blaze Stacking Data'!M24,$I$8='Blaze Stacking Data'!$J$30,'Blaze Stacking Data'!M35,$I$8='Blaze Stacking Data'!$J$41,'Blaze Stacking Data'!M46,$I$8="-","0") -> 0 | J13: =SUM(G13+E13+C13+I13) -> 27 | K13: =K12+J13 -> 164 | L13: =ROUNDDOWN(K13/35,0) -> 4 | M13: =IF(OR(L13=0,L11=L13),"No","Yes") -> Yes | N13: =IF(L13=L12,"No",IF(L13<>L12,"Yes")) -> Yes | O13: =L13*5% -> 0.2
A14: Round 6 | B14: =_xlfn.IFS($C$8='Blaze Stacking Data'!$F$9,'Blaze Stacking Data'!F15,$C$8='Blaze Stacking Data'!$F$19,'Blaze Stacking Data'!F25,$C$8='Blaze Stacking Data'!$F$41,'Blaze Stacking Data'!F47,$C$8="-","") -> S3 | C14: =_xlfn.IFS($C$8='Blaze Stacking Data'!$F$9,'Blaze Stacking Data'!G15,$C$8='Blaze Stacking Data'!$F$19,'Blaze Stacking Data'!G25,$C$8='Blaze Stacking Data'!$F$41,'Blaze Stacking Data'!G47,$C$8="-","0") -> 21 | D14: =_xlfn.IFS($E$8='Blaze Stacking Data'!$H$9,'Blaze Stacking Data'!H15,$E$8='Blaze Stacking Data'!$H$19,'Blaze Stacking Data'!H25,$E$8='Blaze Stacking Data'!$H$30,'Blaze Stacking Data'!H36,$E$8='Blaze Stacking Data'!$H$41,'Blaze Stacking Data'!H47,$E$8="-","") | E14: =_xlfn.IFS($E$8='Blaze Stacking Data'!$H$9,'Blaze Stacking Data'!I15,$E$8='Blaze Stacking Data'!$H$19,'Blaze Stacking Data'!I25,$E$8='Blaze Stacking Data'!$H$30,'Blaze Stacking Data'!I36,$E$8='Blaze Stacking Data'!$H$41,'Blaze Stacking Data'!I47,$E$8="-","0") -> 0 | F14: =_xlfn.IFS($G$8='Blaze Stacking Data'!$J$9,'Blaze Stacking Data'!J15,$G$8='Blaze Stacking Data'!$J$19,'Blaze Stacking Data'!J25,$G$8='Blaze Stacking Data'!$J$30,'Blaze Stacking Data'!J36,$G$8='Blaze Stacking Data'!$J$41,'Blaze Stacking Data'!J47,$G$8="-","") -> S2+S1 | G14: =_xlfn.IFS($G$8='Blaze Stacking Data'!$J$9,'Blaze Stacking Data'!K15,$G$8='Blaze Stacking Data'!$J$19,'Blaze Stacking Data'!K25,$G$8='Blaze Stacking Data'!$J$30,'Blaze Stacking Data'!K36,$G$8='Blaze Stacking Data'!$J$41,'Blaze Stacking Data'!K47,$G$8="-","0") -> 12 | H14: =_xlfn.IFS($I$8='Blaze Stacking Data'!$J$9,'Blaze Stacking Data'!L15,$I$8='Blaze Stacking Data'!$J$19,'Blaze Stacking Data'!L25,$I$8='Blaze Stacking Data'!$J$30,'Blaze Stacking Data'!L36,$I$8='Blaze Stacking Data'!$J$41,'Blaze Stacking Data'!L47,$I$8="-","") | I14: =_xlfn.IFS($I$8='Blaze Stacking Data'!$J$9,'Blaze Stacking Data'!M15,$I$8='Blaze Stacking Data'!$J$19,'Blaze Stacking Data'!M25,$I$8='Blaze Stacking Data'!$J$30,'Blaze Stacking Data'!M36,$I$8='Blaze Stacking Data'!$J$41,'Blaze Stacking Data'!M47,$I$8="-","0") -> 0 | J14: =SUM(G14+E14+C14+I14) -> 33 | K14: =K13+J14 -> 197 | L14: =ROUNDDOWN(K14/35,0) -> 5 | M14: =IF(OR(L14=0,L12=L14),"No","Yes") -> Yes | N14: =IF(L14=L13,"No",IF(L14<>L13,"Yes")) -> Yes | O14: =L14*5% -> 0.25
A15: Round 7 | B15: =_xlfn.IFS($C$8='Blaze Stacking Data'!$F$9,'Blaze Stacking Data'!F16,$C$8='Blaze Stacking Data'!$F$19,'Blaze Stacking Data'!F26,$C$8='Blaze Stacking Data'!$F$41,'Blaze Stacking Data'!F48,$C$8="-","") -> S2 | C15: =_xlfn.IFS($C$8='Blaze Stacking Data'!$F$9,'Blaze Stacking Data'!G16,$C$8='Blaze Stacking Data'!$F$19,'Blaze Stacking Data'!G26,$C$8='Blaze Stacking Data'!$F$41,'Blaze Stacking Data'!G48,$C$8="-","0") -> 15 | D15: =_xlfn.IFS($E$8='Blaze Stacking Data'!$H$9,'Blaze Stacking Data'!H16,$E$8='Blaze Stacking Data'!$H$19,'Blaze Stacking Data'!H26,$E$8='Blaze Stacking Data'!$H$30,'Blaze Stacking Data'!H37,$E$8='Blaze Stacking Data'!$H$41,'Blaze Stacking Data'!H48,$E$8="-","") | E15: =_xlfn.IFS($E$8='Blaze Stacking Data'!$H$9,'Blaze Stacking Data'!I16,$E$8='Blaze Stacking Data'!$H$19,'Blaze Stacking Data'!I26,$E$8='Blaze Stacking Data'!$H$30,'Blaze Stacking Data'!I37,$E$8='Blaze Stacking Data'!$H$41,'Blaze Stacking Data'!I48,$E$8="-","0") -> 0 | F15: =_xlfn.IFS($G$8='Blaze Stacking Data'!$J$9,'Blaze Stacking Data'!J16,$G$8='Blaze Stacking Data'!$J$19,'Blaze Stacking Data'!J26,$G$8='Blaze Stacking Data'!$J$30,'Blaze Stacking Data'!J37,$G$8='Blaze Stacking Data'!$J$41,'Blaze Stacking Data'!J48,$G$8="-","") -> S3+S2 | G15: =_xlfn.IFS($G$8='Blaze Stacking Data'!$J$9,'Blaze Stacking Data'!K16,$G$8='Blaze Stacking Data'!$J$19,'Blaze Stacking Data'!K26,$G$8='Blaze Stacking Data'!$J$30,'Blaze Stacking Data'!K37,$G$8='Blaze Stacking Data'!$J$41,'Blaze Stacking Data'!K48,$G$8="-","0") -> 20 | H15: =_xlfn.IFS($I$8='Blaze Stacking Data'!$J$9,'Blaze Stacking Data'!L16,$I$8='Blaze Stacking Data'!$J$19,'Blaze Stacking Data'!L26,$I$8='Blaze Stacking Data'!$J$30,'Blaze Stacking Data'!L37,$I$8='Blaze Stacking Data'!$J$41,'Blaze Stacking Data'!L48,$I$8="-","") | I15: =_xlfn.IFS($I$8='Blaze Stacking Data'!$J$9,'Blaze Stacking Data'!M16,$I$8='Blaze Stacking Data'!$J$19,'Blaze Stacking Data'!M26,$I$8='Blaze Stacking Data'!$J$30,'Blaze Stacking Data'!M37,$I$8='Blaze Stacking Data'!$J$41,'Blaze Stacking Data'!M48,$I$8="-","0") -> 0 | J15: =SUM(G15+E15+C15+I15) -> 35 | K15: =K14+J15 -> 232 | L15: =ROUNDDOWN(K15/35,0) -> 6 | M15: =IF(OR(L15=0,L13=L15),"No","Yes") -> Yes | N15: =IF(L15=L14,"No",IF(L15<>L14,"Yes")) -> Yes | O15: =L15*5% -> 0.3
A16: Total Blaze Stacks Generated | C16: =SUM(C9:C15) -> 114 | E16: =SUM(E9:E15) -> 0 | G16: =SUM(G9:G15) -> 118 | I16: =SUM(I9:I15) -> 0
A17: Average Blaze Stacks/Round | C17: =SUM(C9:C15)/7 -> 16.285714 | E17: =SUM(E9:E15)/7 -> 0 | G17: =SUM(G9:G15)/7 -> 16.857143 | I17: =SUM(I9:I15)/7 -> 0

Sheet Blaze Stacking Data
A1: Blaze stacking Mechanic for each relevant burn dolls: | F1: Fortifications | G1: Lewis | H1: V0 | I1: V2 | J1: V6 | K1: -
G2: Sakura | H2: V0 | I2: V2 | J2: V4 | K2: V6 | L2: -
A3: Doll | B3: Source1 | C3: Supplementary Sources (Blaze Stacks) | G3: Loreley | H3: V0 | I3: V1 | J3: V2 | K3: V3 | L3: -
A4: Loreley | B4: Summon attack + ULT | C4: Fixed Key (10 at start of battle) | G4: Ots-14 | H4: V0 | I4: V1 | J4: -
A5: Sakura | B5: Sakura Mark + Ult Passive | C5: Fixed Key (1 extra sakura mark (2 blaze) at start of battle)
A6: Lewis | B6: Volley Trigger + Ult Rank 3 Toys | C6: -
A7: Ots-14 | B7: S1 | C7: - | E7: Single Target
F8: Skill | G8: Lewis | H8: Skill | I8: Sakura | J8: Skill | K8: Loreley | L8: Skill | M8: Ots-14 | N8: Total Blaze Count | O8: Tallied | P8: Ember
E9: Duplicates | F9: V0 | H9: V0 | J9: V0 | L9: V0
E10: Turn 1 | F10: S2 | G10: 6 | H10: S1+S3 | I10: 6 | J10: S3+S2 | K10: =10+8+3 -> 21 | L10: S2+S1 | M10: 13 | N10: =SUM(K10,I10,G10,M10) -> 46 | O10: =N10 -> 46 | P10: =ROUNDDOWN(O10/35,0) -> 1
E11: Turn 2 | F11: S1 | G11: 6 | H11: S1+S2 | I11: 12 | J11: S2/S1 +S0 | K11: =3 -> 3 | L11: S2+S0 | M11: 0 | N11: =SUM(K11,I11,G11,M11) -> 21 | O11: =O10+N11 -> 67 | P11: =ROUNDDOWN(O11/35,0) -> 1
E12: Turn 3 | F12: S3 | G12: 12 | H12: S2 | I12: 10 | J12: S2/S1 +S0 | K12: 3 | L12: S2+S1 | M12: 13 | N12: =SUM(K12,I12,G12,M12) -> 38 | O12: =O11+N12 -> 105 | P12: =ROUNDDOWN(O12/35,0) -> 3
E13: Turn 4 | F13: S2 | G13: 6 | H13: S1+S3 | I13: 4 | J13: S3+S2 | K13: =8+3 -> 11 | L13: S2+S0 | M13: 0 | N13: =SUM(K13,I13,G13,M13) -> 21 | O13: =O12+N13 -> 126 | P13: =ROUNDDOWN(O13/35,0) -> 3
E14: Turn 5 | F14: S1 | G14: 6 | H14: S1+S2 | I14: 12 | J14: S2/S1 +S0 | K14: 3 | L14: S2+S1 | M14: 13 | N14: =SUM(K14,I14,G14,M14) -> 34 | O14: =O13+N14 -> 160 | P14: =ROUNDDOWN(O14/35,0) -> 4
E15: Turn 6 | F15: S3 | G15: 12 | H15: S2 | I15: 10 | J15: S2/S1 +S0 | K15: 3 | L15: S2+S0 | M15: 0 | N15: =SUM(K15,I15,G15,M15) -> 25 | O15: =O14+N15 -> 185 | P15: =ROUNDDOWN(O15/35,0) -> 5
E16: Turn 7 | F16: S2 | G16: 6 | H16: S3 | I16: 4 | J16: S3+S2 | K16: =8+3 -> 11 | L16: S2+S1 | M16: 13 | N16: =SUM(K16,I16,G16,M16) -> 34 | O16: =O15+N16 -> 219 | P16: =ROUNDDOWN(O16/35,0) -> 6
G17: =SUM(G10:G16) -> 54 | I17: =SUM(I10:I16) -> 58 | K17: =SUM(K10:K16) -> 55 | M17: =SUM(M10:M16) -> 52
F18: Skill | G18: Lewis | H18: Skill | I18: Sakura | J18: Skill | K18: Loreley | L18: Skill | M18: Ots-14 | N18: Total Blaze Count | O18: Tallied | P18: Ember
E19: Duplicates | F19: V2 | H19: V2 | J19: V1 | L19: V1
E20: Turn 1 | F20: S2 | G20: 6 | H20: S1+S3 | I20: 6 | J20: S3+S2 | K20: =10+8+3+3 -> 24 | L20: S2+S1 | M20: 13 | N20: =SUM(K20,I20,G20,M20) -> 49 | O20: =N20 -> 49 | P20: =ROUNDDOWN(O20/35,0) -> 1
E21: Turn 2 | F21: S1 | G21: 6 | H21: S1+S2 | I21: 12 | J21: S2/S1 +S0 | K21: =3+3+3 -> 9 | L21: S2+S1 | M21: 13 | N21: =SUM(K21,I21,G21,M21) -> 40 | O21: =O20+N21 -> 89 | P21: =ROUNDDOWN(O21/35,0) -> 2
E22: Turn 3 | F22: S3 | G22: 12 | H22: S1+S2 | I22: 12 | J22: S2/S1 +S0 | K22: =3+3+3 -> 9 | L22: S2+S1 | M22: 13 | N22: =SUM(K22,I22,G22,M22) -> 46 | O22: =O21+N22 -> 135 | P22: =ROUNDDOWN(O22/35,0) -> 3
E23: Turn 4 | F23: S3 | G23: 12 | H23: S3 | I23: 4 | J23: S3+S2 | K23: =8+3+3+3 -> 17 | L23: S2+S1 | M23: 13 | N23: =SUM(K23,I23,G23,M23) -> 46 | O23: =O22+N23 -> 181 | P23: =ROUNDDOWN(O23/35,0) -> 5
E24: Turn 5 | F24: S2 | G24: 6 | H24: S1+S2 | I24: 12 | J24: S2/S1 +S0 | K24: =3+3+3 -> 9 | L24: S2+S1 | M24: 13 | N24: =SUM(K24,I24,G24,M24) -> 40 | O24: =O23+N24 -> 221 | P24: =ROUNDDOWN(O24/35,0) -> 6
E25: Turn 6 | F25: S3 | G25: 12 | H25: S1+S2 | I25: 12 | J25: S2/S1 +S0 | K25: =3+3+3 -> 9 | L25: S2+S1 | M25: 13 | N25: =SUM(K25,I25,G25,M25) -> 46 | O25: =O24+N25 -> 267 | P25: =ROUNDDOWN(O25/35,0) -> 7
E26: Turn 7 | F26: S2 | G26: 6 | H26: S1+S3 | I26: 4 | J26: S3+S2 | K26: =8+3+3+3 -> 17 | L26: S2+S1 | M26: 13 | N26: =SUM(K26,I26,G26,M26) -> 40 | O26: =O25+N26 -> 307 | P26: =ROUNDDOWN(O26/35,0) -> 8
G27: =SUM(G20:G26) -> 60 | I27: =SUM(I20:I26) -> 62 | K27: =SUM(K20:K26) -> 94 | M27: =SUM(M20:M26) -> 91
F29: Skill | G29: Lewis | H29: Skill | I29: Sakura | J29: Skill | K29: Loreley | N29: Total Blaze Count | O29: Tallied | P29: Ember
E30: Duplicates | F30: V2 | H30: V4 | J30: V2
E31: Turn 1 | F31: S2 | G31: 6 | H31: S1+S3 | I31: 6 | J31: S3+S2 | K31: =10+8+3+3+3+3 -> 30 | N31: =SUM(K31,I31,G31) -> 42 | O31: =N31 -> 42 | P31: =ROUNDDOWN(O31/35,0) -> 1
E32: Turn 2 | F32: S1 | G32: 6 | H32: S1+S2 | I32: 14 | J32: S2+S1 | K32: =3+3+3+3 -> 12 | N32: =SUM(K32,I32,G32) -> 32 | O32: =O31+N32 -> 74 | P32: =ROUNDDOWN(O32/35,0) -> 2
E33: Turn 3 | F33: S3 | G33: 12 | H33: S1+S2 | I33: 14 | J33: S2+S1 | K33: =3+3+3+3 -> 12 | N33: =SUM(K33,I33,G33) -> 38 | O33: =O32+N33 -> 112 | P33: =ROUNDDOWN(O33/35,0) -> 3
E34: Turn 4 | F34: S3 | G34: 12 | H34: S3 | I34: 4 | J34: S3+S2 | K34: =8+3+3+3+3 -> 20 | N34: =SUM(K34,I34,G34) -> 36 | O34: =O33+N34 -> 148 | P34: =ROUNDDOWN(O34/35,0) -> 4
E35: Turn 5 | F35: S2 | G35: 6 | H35: S1+S2 | I35: 14 | J35: S2+S1 | K35: =3+3+3+3 -> 12 | N35: =SUM(K35,I35,G35) -> 32 | O35: =O34+N35 -> 180 | P35: =ROUNDDOWN(O35/35,0) -> 5
E36: Turn 6 | F36: S3 | G36: 12 | H36: S1+S2 | I36: 14 | J36: S2+S1 | K36: =3+3+3+3 -> 12 | N36: =SUM(K36,I36,G36) -> 38 | O36: =O35+N36 -> 218 | P36: =ROUNDDOWN(O36/35,0) -> 6
E37: Turn 7 | F37: S2 | G37: 6 | H37: S1+S3 | I37: 4 | J37: S3+S2 | K37: =8+3+3+3+3 -> 20 | N37: =SUM(K37,I37,G37) -> 30 | O37: =O36+N37 -> 248 | P37: =ROUNDDOWN(O37/35,0) -> 7
G38: =SUM(G31:G37) -> 60 | I38: =SUM(I31:I37) -> 70 | K38: =SUM(K31:K37) -> 118
F40: Skill | G40: Lewis | H40: Skill | I40: Sakura | J40: Skill | K40: Loreley | N40: Total Blaze Count | O40: Tallied | P40: Ember
E41: Duplicates | F41: V6 | H41: V6 | J41: V3
E42: Turn 1 | F42: S2 | G42: ='Lewis Conf. Index'!M24 -> 6 | H42: S1+S3 | I42: 12 | J42: S3+S2 | K42: =10+12+3+3+3+3 -> 34 | N42: =SUM(K42,I42,G42) -> 52 | O42: =N42 -> 52 | P42: =ROUNDDOWN(O42/35,0) -> 1
...

Sheet Sakura Conf. Index
A1: Sakura + Lewis V0 | C1: CI = Confectance Index | E1: note: S3 doesn't generate Blaze Stacks but apply "Good Fortune" buff, to generate 1 Sakura mark before Sakura cast s1 and/or s2 for non ult turns | R1: note: no Lind V0 to trigger Lewis AOE cheese, and assumes all enemy is tanky and spreads out enough so S1 sakura can't hit multiple enemies
E2: Equipped Fixed key 1 for extra sakura mark at turn 1
B3: Sakura Mark | C3: V0 | E3: V0 | Q3: V0 | R3: Total enemies | S3: 3
A4: Turn 1 | B4: 5 | C4: S1+S3 | E4: Start turn generation | F4: Current CI | G4: Skill | H4: Cost | I4: Generated | J4: Total at End Turn | K4: Sakura Mark | L4: Sakura Blaze | M4: Lewis Blaze | N4: Total Blaze | O4: Ember | Q4: Start turn generation | R4: Current CI | S4: Skill | T4: Cost | U4: Generated | V4: Total at End Turn | W4: Sakura Mark | X4: Sakura Blaze | Y4: Lewis Blaze | Z4: Total Blaze | AA4: Ember
A5: Turn 2 | B5: 6 | C5: S1+S2 | E5: 2 | F5: 5 | G5: S1+S3 | H5: 3 | I5: 2 | J5: =SUM(F5-H5+I5) -> 4 | K5: 3 | L5: =K5*2 -> 6 | M5: 6 | N5: =M5+L5 -> 12 | O5: =ROUNDDOWN(N5/35,0) -> 0 | Q5: 2 | R5: 5 | S5: S1+S3 | T5: 3 | U5: 2 | V5: =SUM(R5-T5+U5) -> 4 | W5: =S3*3 -> 9 | X5: =W5*2 -> 18 | Y5: 6 | Z5: =Y5+X5 -> 24 | AA5: =ROUNDDOWN(Z5/35,0) -> 0
A6: Turn 3 | B6: 5 | C6: S2 | E6: 2 | F6: =IF(J5+E6>6,6,J5+E6) -> 6 | G6: S1+S2 | H6: 4 | I6: 0 | J6: =SUM(F6-H6+I6) -> 2 | K6: 6 | L6: =K6*2 -> 12 | M6: 6 | N6: =N5+M6+L6 -> 30 | O6: =ROUNDDOWN(N6/35,0) -> 0 | Q6: 2 | R6: =IF(V5+Q6>6,6,V5+Q6) -> 6 | S6: S1+S2 | T6: 4 | U6: 0 | V6: =SUM(R6-T6+U6) -> 2 | W6: =4+S3*2 -> 10 | X6: =W6*2 -> 20 | Y6: 6 | Z6: =Z5+Y6+X6 -> 50 | AA6: =ROUNDDOWN(Z6/35,0) -> 1
A7: Turn 4 | B7: 2 | C7: S3 | E7: 2 | F7: =IF(J6+E7>6,6,J6+E7) -> 4 | G7: S2 | H7: 2 | I7: 0 | J7: =SUM(F7-H7+I7) -> 2 | K7: 5 | L7: =K7*2 -> 10 | M7: 12 | N7: =N6+M7+L7 -> 52 | O7: =ROUNDDOWN(N7/35,0) -> 1 | Q7: 2 | R7: =IF(V6+Q7>6,6,V6+Q7) -> 4 | S7: S2 | T7: 2 | U7: 0 | V7: =SUM(R7-T7+U7) -> 2 | W7: =3+S3*2 -> 9 | X7: =W7*2 -> 18 | Y7: 12 | Z7: =Z6+Y7+X7 -> 80 | AA7: =ROUNDDOWN(Z7/35,0) -> 2
A8: Turn 5 | B8: 6 | C8: S1+S2 | E8: 2 | F8: =IF(J7+E8>6,6,J7+E8) -> 4 | G8: S1+S3 | H8: 3 | I8: 2 | J8: =SUM(F8-H8+I8) -> 3 | K8: 2 | L8: =K8*2 -> 4 | M8: 6 | N8: =N7+M8+L8 -> 62 | O8: =ROUNDDOWN(N8/35,0) -> 1 | Q8: 2 | R8: =IF(V7+Q8>6,6,V7+Q8) -> 4 | S8: S1+S3 | T8: 3 | U8: 2 | V8: =SUM(R8-T8+U8) -> 3 | W8: =S3*2 -> 6 | X8: =W8*2 -> 12 | Y8: 6 | Z8: =Z7+Y8+X8 -> 98 | AA8: =ROUNDDOWN(Z8/35,0) -> 2
A9: Turn 6 | B9: 5 | C9: S2 | E9: 2 | F9: =IF(J8+E9>6,6,J8+E9) -> 5 | G9: S1+S2 | H9: 5 | I9: 0 | J9: =SUM(F9-H9+I9) -> 0 | K9: 6 | L9: =K9*2 -> 12 | M9: 6 | N9: =N8+M9+L9 -> 80 | O9: =ROUNDDOWN(N9/35,0) -> 2 | Q9: 2 | R9: =IF(V8+Q9>6,6,V8+Q9) -> 5 | S9: S1+S2 | T9: 5 | U9: 0 | V9: =SUM(R9-T9+U9) -> 0 | W9: =4+S3*2 -> 10 | X9: =W9*2 -> 20 | Y9: 6 | Z9: =Z8+Y9+X9 -> 124 | AA9: =ROUNDDOWN(Z9/35,0) -> 3
A10: Turn 7 | B10: 2 | C10: S3 | E10: 2 | F10: =IF(J9+E10>6,6,J9+E10) -> 2 | G10: S2 | H10: 2 | I10: 0 | J10: =SUM(F10-H10+I10) -> 0 | K10: 5 | L10: =K10*2 -> 10 | M10: 12 | N10: =N9+M10+L10 -> 102 | O10: =ROUNDDOWN(N10/35,0) -> 2 | Q10: 2 | R10: =IF(V9+Q10>6,6,V9+Q10) -> 2 | S10: S2 | T10: 2 | U10: 0 | V10: =SUM(R10-T10+U10) -> 0 | W10: =3+S3*2 -> 9 | X10: =W10*2 -> 18 | Y10: 12 | Z10: =Z9+Y10+X10 -> 154 | AA10: =ROUNDDOWN(Z10/35,0) -> 4
E11: 2 | F11: =IF(J10+E11>6,6,J10+E11) -> 2 | G11: S3 | H11: 2 | I11: 2 | J11: =SUM(F11-H11+I11) -> 2 | K11: 2 | L11: =K11*2 -> 4 | M11: 6 | N11: =N10+M11+L11 -> 112 | O11: =ROUNDDOWN(N11/35,0) -> 3 | Q11: 2 | R11: =IF(V10+Q11>6,6,V10+Q11) -> 2 | S11: S3 | T11: 2 | U11: 2 | V11: =SUM(R11-T11+U11) -> 2 | W11: =S3*2 -> 6 | X11: =W11*2 -> 12 | Y11: 6 | Z11: =Z10+Y11+X11 -> 172 | AA11: =ROUNDDOWN(Z11/35,0) -> 4
E13: V2 | Q13: V2
E14: Start turn generation | F14: Current CI | G14: Skill | H14: Cost | I14: Generated | J14: Total at End Turn | K14: Sakura Mark | L14: Sakura Blaze | M14: Lewis Blaze | N14: Total Blaze | O14: Ember | Q14: Start turn generation | R14: Current CI | S14: Skill | T14: Cost | U14: Generated | V14: Total at End Turn | W14: Sakura Mark | X14: Sakura Blaze | Y14: Lewis Blaze | Z14: Total Blaze | AA14: Ember
E15: 2 | F15: 5 | G15: S1+S3 | H15: 2 | I15: 2 | J15: =SUM(F15-H15+I15) -> 5 | K15: 3 | L15: =K15*2 -> 6 | M15: 6 | N15: =M15+L15 -> 12 | O15: =ROUNDDOWN(N15/35,0) -> 0 | Q15: 2 | R15: 5 | S15: S1+S3 | T15: 2 | U15: 2 | V15: =SUM(R15-T15+U15) -> 5 | W15: =S3*3 -> 9 | X15: =W15*2 -> 18 | Y15: 6 | Z15: =Y15+X15 -> 24 | AA15: =ROUNDDOWN(Z15/35,0) -> 0
E16: 2 | F16: =IF(J15+E16>6,J15+E16-1,J15+E16) -> 6 | G16: S1+S2 | H16: 4 | I16: 0 | J16: =SUM(F16-H16+I16) -> 2 | K16: 6 | L16: =K16*2 -> 12 | M16: 6 | N16: =N15+M16+L16 -> 30 | O16: =ROUNDDOWN(N16/35,0) -> 0 | Q16: 2 | R16: =IF(V15+Q16>6,V15+Q16-1,V15+Q16) -> 6 | S16: S1+S2 | T16: 4 | U16: 0 | V16: =SUM(R16-T16+U16) -> 2 | W16: =4+S3*2 -> 10 | X16: =W16*2 -> 20 | Y16: 6 | Z16: =Z15+Y16+X16 -> 50 | AA16: =ROUNDDOWN(Z16/35,0) -> 1
E17: 2 | F17: =IF(J16+E17>6,J16+E17-1,J16+E17) -> 4 | G17: S1+S2 | H17: 4 | I17: 0 | J17: =SUM(F17-H17+I17) -> 0 | K17: 6 | L17: =K17*2 -> 12 | M17: 12 | N17: =N16+M17+L17 -> 54 | O17: =ROUNDDOWN(N17/35,0) -> 1 | Q17: 2 | R17: =IF(V16+Q17>6,V16+Q17-1,V16+Q17) -> 4 | S17: S1+S2 | T17: 4 | U17: 0 | V17: =SUM(R17-T17+U17) -> 0 | W17: =4+S3*2 -> 10 | X17: =W17*2 -> 20 | Y17: 12 | Z17: =Z16+Y17+X17 -> 82 | AA17: =ROUNDDOWN(Z17/35,0) -> 2
E18: 2 | F18: =IF(J17+E18>6,J17+E18-1,J17+E18) -> 2 | G18: S3 | H18: 0 | I18: 2 | J18: =SUM(F18-H18+I18) -> 4 | K18: 2 | L18: =K18*2 -> 4 | M18: 6 | N18: =N17+M18+L18 -> 64 | O18: =ROUNDDOWN(N18/35,0) -> 1 | Q18: 2 | R18: =IF(V17+Q18>6,V17+Q18-1,V17+Q18) -> 2 | S18: S3 | T18: 0 | U18: 2 | V18: =SUM(R18-T18+U18) -> 4 | W18: =S3*2 -> 6 | X18: =W18*2 -> 12 | Y18: 6 | Z18: =Z17+Y18+X18 -> 100 | AA18: =ROUNDDOWN(Z18/35,0) -> 2
E19: 2 | F19: =IF(J18+E19>6,J18+E19-1,J18+E19) -> 6 | G19: S1+S2 | H19: 4 | I19: 0 | J19: =SUM(F19-H19+I19) -> 2 | K19: 6 | L19: =K19*2 -> 12 | M19: 6 | N19: =N18+M19+L19 -> 82 | O19: =ROUNDDOWN(N19/35,0) -> 2 | Q19: 2 | R19: =IF(V18+Q19>6,V18+Q19-1,V18+Q19) -> 6 | S19: S1+S2 | T19: 4 | U19: 0 | V19: =SUM(R19-T19+U19) -> 2 | W19: =4+S3*2 -> 10 | X19: =W19*2 -> 20 | Y19: 6 | Z19: =Z18+Y19+X19 -> 126 | AA19: =ROUNDDOWN(Z19/35,0) -> 3
E20: 2 | F20: =IF(J19+E20>6,J19+E20-1,J19+E20) -> 4 | G20: S1+S2 | H20: 4 | I20: 0 | J20: =SUM(F20-H20+I20) -> 0 | K20: 6 | L20: =K20*2 -> 12 | M20: 12 | N20: =N19+M20+L20 -> 106 | O20: =ROUNDDOWN(N20/35,0) -> 3 | Q20: 2 | R20: =IF(V19+Q20>6,V19+Q20-1,V19+Q20) -> 4 | S20: S1+S2 | T20: 4 | U20: 0 | V20: =SUM(R20-T20+U20) -> 0 | W20: =4+S3*2 -> 10 | X20: =W20*2 -> 20 | Y20: 12 | Z20: =Z19+Y20+X20 -> 158 | AA20: =ROUNDDOWN(Z20/35,0) -> 4
E21: 2 | F21: =IF(J20+E21>6,J20+E21-1,J20+E21) -> 2 | G21: S1+S3 | H21: 2 | I21: 2 | J21: =SUM(F21-H21+I21) -> 2 | K21: 2 | L21: =K21*2 -> 4 | M21: 6 | N21: =N20+M21+L21 -> 116 | O21: =ROUNDDOWN(N21/35,0) -> 3 | Q21: 2 | R21: =IF(V20+Q21>6,V20+Q21-1,V20+Q21) -> 2 | S21: S1+S3 | T21: 2 | U21: 2 | V21: =SUM(R21-T21+U21) -> 2 | W21: =S3*2 -> 6 | X21: =W21*2 -> 12 | Y21: 6 | Z21: =Z20+Y21+X21 -> 176 | AA21: =ROUNDDOWN(Z21/35,0) -> 5
E23: V4 | Q23: V4
E24: Start turn generation | F24: Current CI | G24: Skill | H24: Cost | I24: Generated | J24: Total at End Turn | K24: Sakura Mark | L24: Sakura Blaze | M24: Lewis Blaze | N24: Total Blaze | O24: Ember | Q24: Start turn generation | R24: Current CI | S24: Skill | T24: Cost | U24: Generated | V24: Total at End Turn | W24: Sakura Mark | X24: Sakura Blaze | Y24: Lewis Blaze | Z24: Total Blaze | AA24: Ember
E25: 2 | F25: 5 | G25: S1+S3 | H25: 2 | I25: 2 | J25: =SUM(F25-H25+I25) -> 5 | K25: 3 | L25: =K25*2 -> 6 | M25: 6 | N25: =M25+L25 -> 12 | O25: =ROUNDDOWN(N25/35,0) -> 0 | Q25: 2 | R25: 5 | S25: S1+S3 | T25: 2 | U25: 2 | V25: =SUM(R25-T25+U25) -> 5 | W25: =S3*3 -> 9 | X25: =W25*2 -> 18 | Y25: 6 | Z25: =Y25+X25 -> 24 | AA25: =ROUNDDOWN(Z25/35,0) -> 0
E26: 2 | F26: =IF(J25+E26>6,J25+E26-1,J25+E26) -> 6 | G26: S1+S2 | H26: 4 | I26: 0 | J26: =SUM(F26-H26+I26) -> 2 | K26: 7 | L26: =K26*2 -> 14 | M26: 6 | N26: =N25+M26+L26 -> 32 | O26: =ROUNDDOWN(N26/35,0) -> 0 | Q26: 2 | R26: =IF(V25+Q26>6,V25+Q26-1,V25+Q26) -> 6 | S26: S1+S2 | T26: 4 | U26: 0 | V26: =SUM(R26-T26+U26) -> 2 | W26: =5+S3*2 -> 11 | X26: =W26*2 -> 22 | Y26: 6 | Z26: =Z25+Y26+X26 -> 52 | AA26: =ROUNDDOWN(Z26/35,0) -> 1
E27: 2 | F27: =IF(J26+E27>6,J26+E27-1,J26+E27) -> 4 | G27: S1+S2 | H27: 4 | I27: 0 | J27: =SUM(F27-H27+I27) -> 0 | K27: 7 | L27: =K27*2 -> 14 | M27: 12 | N27: =N26+M27+L27 -> 58 | O27: =ROUNDDOWN(N27/35,0) -> 1 | Q27: 2 | R27: =IF(V26+Q27>6,V26+Q27-1,V26+Q27) -> 4 | S27: S1+S2 | T27: 4 | U27: 0 | V27: =SUM(R27-T27+U27) -> 0 | W27: =5+S3*2 -> 11 | X27: =W27*2 -> 22 | Y27: 12 | Z27: =Z26+Y27+X27 -> 86 | AA27: =ROUNDDOWN(Z27/35,0) -> 2
E28: 2 | F28: =IF(J27+E28>6,J27+E28-1,J27+E28) -> 2 | G28: S3 | H28: 0 | I28: 2 | J28: =SUM(F28-H28+I28) -> 4 | K28: 2 | L28: =K28*2 -> 4 | M28: 6 | N28: =N27+M28+L28 -> 68 | O28: =ROUNDDOWN(N28/35,0) -> 1 | Q28: 2 | R28: =IF(V27+Q28>6,V27+Q28-1,V27+Q28) -> 2 | S28: S3 | T28: 0 | U28: 2 | V28: =SUM(R28-T28+U28) -> 4 | W28: =S3*2 -> 6 | X28: =W28*2 -> 12 | Y28: 6 | Z28: =Z27+Y28+X28 -> 104 | AA28: =ROUNDDOWN(Z28/35,0) -> 2
E29: 2 | F29: =IF(J28+E29>6,J28+E29-1,J28+E29) -> 6 | G29: S1+S2 | H29: 4 | I29: 0 | J29: =SUM(F29-H29+I29) -> 2 | K29: 7 | L29: =K29*2 -> 14 | M29: 6 | N29: =N28+M29+L29 -> 88 | O29: =ROUNDDOWN(N29/35,0) -> 2 | Q29: 2 | R29: =IF(V28+Q29>6,V28+Q29-1,V28+Q29) -> 6 | S29: S1+S2 | T29: 4 | U29: 0 | V29: =SUM(R29-T29+U29) -> 2 | W29: =5+S3*2 -> 11 | X29: =W29*2 -> 22 | Y29: 6 | Z29: =Z28+Y29+X29 -> 132 | AA29: =ROUNDDOWN(Z29/35,0) -> 3
E30: 2 | F30: =IF(J29+E30>6,J29+E30-1,J29+E30) -> 4 | G30: S1+S2 | H30: 4 | I30: 0 | J30: =SUM(F30-H30+I30) -> 0 | K30: 7 | L30: =K30*2 -> 14 | M30: 12 | N30: =N29+M30+L30 -> 114 | O30: =ROUNDDOWN(N30/35,0) -> 3 | Q30: 2 | R30: =IF(V29+Q30>6,V29+Q30-1,V29+Q30) -> 4 | S30: S1+S2 | T30: 4 | U30: 0 | V30: =SUM(R30-T30+U30) -> 0 | W30: =5+S3*2 -> 11 | X30: =W30*2 -> 22 | Y30: 12 | Z30: =Z29+Y30+X30 -> 166 | AA30: =ROUNDDOWN(Z30/35,0) -> 4
E31: 2 | F31: =IF(J30+E31>6,J30+E31-1,J30+E31) -> 2 | G31: S1+S3 | H31: 2 | I31: 2 | J31: =SUM(F31-H31+I31) -> 2 | K31: 2 | L31: =K31*2 -> 4 | M31: 6 | N31: =N30+M31+L31 -> 124 | O31: =ROUNDDOWN(N31/35,0) -> 3 | Q31: 2 | R31: =IF(V30+Q31>6,V30+Q31-1,V30+Q31) -> 2 | S31: S1+S3 | T31: 2 | U31: 2 | V31: =SUM(R31-T31+U31) -> 2 | W31: =S3*2 -> 6 | X31: =W31*2 -> 12 | Y31: 6 | Z31: =Z30+Y31+X31 -> 184 | AA31: =ROUNDDOWN(Z31/35,0) -> 5
E33: V6 | Q33: V6
E34: Start turn generation | F34: Current CI | G34: Skill | H34: Cost | I34: Generated | J34: Total at End Turn | K34: Sakura Mark | L34: V6 Sakura buff | M34: Sakura Blaze | N34: Lewis Blaze | O34: Total Blaze | P34: Ember | Q34: Start turn generation | R34: Current CI | S34: Skill | T34: Cost | U34: Generated | V34: Total at End Turn | W34: Sakura Mark | X34: V6 Sakura buff | Y34: Sakura Blaze | Z34: Lewis Blaze | AA34: Total Blaze | AB34: Ember
E35: 2 | F35: 5 | G35: S1+S3 | H35: 2 | I35: 2 | J35: =SUM(F35-H35+I35) -> 5 | K35: 3 | L35: 3 | M35: =SUM(K35:L35)*2 -> 12 | N35: 6 | O35: =N35+M35 -> 18 | P35: =ROUNDDOWN(O35/35,0) -> 0 | Q35: 2 | R35: 5 | S35: S1+S3 | T35: 2 | U35: 2 | V35: =SUM(R35-T35+U35) -> 5 | W35: =S3*3 -> 9 | X35: 3 | Y35: =SUM(W35:X35)*2 -> 24 | Z35: 6 | AA35: =Z35+Y35 -> 30 | AB35: =ROUNDDOWN(AA35/35,0) -> 0
E36: 2 | F36: =IF(J35+E36>6,J35+E36-1,J35+E36) -> 6 | G36: S1+S2 | H36: 4 | I36: 0 | J36: =SUM(F36-H36+I36) -> 2 | K36: 7 | L36: 3 | M36: =SUM(K36:L36)*2 -> 20 | N36: 6 | O36: =O35+N36+M36 -> 44 | P36: =ROUNDDOWN(O36/35,0) -> 1 | Q36: 2 | R36: =IF(V35+Q36>6,V35+Q36-1,V35+Q36) -> 6 | S36: S1+S2 | T36: 4 | U36: 0 | V36: =SUM(R36-T36+U36) -> 2 | W36: =5+S3*2 -> 11 | X36: 3 | Y36: =SUM(W36:X36)*2 -> 28 | Z36: 6 | AA36: =AA35+Z36+Y36 -> 64 | AB36: =ROUNDDOWN(AA36/35,0) -> 1
E37: 2 | F37: =IF(J36+E37>6,J36+E37-1,J36+E37) -> 4 | G37: S1+S2 | H37: 4 | I37: 0 | J37: =SUM(F37-H37+I37) -> 0 | K37: 7 | L37: 3 | M37: =SUM(K37:L37)*2 -> 20 | N37: 12 | O37: =O36+N37+M37 -> 76 | P37: =ROUNDDOWN(O37/35,0) -> 2 | Q37: 2 | R37: =IF(V36+Q37>6,V36+Q37-1,V36+Q37) -> 4 | S37: S1+S2 | T37: 4 | U37: 0 | V37: =SUM(R37-T37+U37) -> 0 | W37: =5+S3*2 -> 11 | X37: 3 | Y37: =SUM(W37:X37)*2 -> 28 | Z37: 12 | AA37: =AA36+Z37+Y37 -> 104 | AB37: =ROUNDDOWN(AA37/35,0) -> 2
E38: 2 | F38: =IF(J37+E38>6,J37+E38-1,J37+E38) -> 2 | G38: S3 | H38: 0 | I38: 2 | J38: =SUM(F38-H38+I38) -> 4 | K38: 2 | L38: 3 | M38: =SUM(K38:L38)*2 -> 10 | N38: 6 | O38: =O37+N38+M38 -> 92 | P38: =ROUNDDOWN(O38/35,0) -> 2 | Q38: 2 | R38: =IF(V37+Q38>6,V37+Q38-1,V37+Q38) -> 2 | S38: S3 | T38: 0 | U38: 2 | V38: =SUM(R38-T38+U38) -> 4 | W38: =S3*2 -> 6 | X38: 3 | Y38: =SUM(W38:X38)*2 -> 18 | Z38: 6 | AA38: =AA37+Z38+Y38 -> 128 | AB38: =ROUNDDOWN(AA38/35,0) -> 3
E39: 2 | F39: =IF(J38+E39>6,J38+E39-1,J38+E39) -> 6 | G39: S1+S2 | H39: 4 | I39: 0 | J39: =SUM(F39-H39+I39) -> 2 | K39: 7 | L39: 3 | M39: =SUM(K39:L39)*2 -> 20 | N39: 6 | O39: =O38+N39+M39 -> 118 | P39: =ROUNDDOWN(O39/35,0) -> 3 | Q39: 2 | R39: =IF(V38+Q39>6,V38+Q39-1,V38+Q39) -> 6 | S39: S1+S2 | T39: 4 | U39: 0 | V39: =SUM(R39-T39+U39) -> 2 | W39: =5+S3*2 -> 11 | X39: 3 | Y39: =SUM(W39:X39)*2 -> 28 | Z39: 6 | AA39: =AA38+Z39+Y39 -> 162 | AB39: =ROUNDDOWN(AA39/35,0) -> 4
E40: 2 | F40: =IF(J39+E40>6,J39+E40-1,J39+E40) -> 4 | G40: S1+S2 | H40: 4 | I40: 0 | J40: =SUM(F40-H40+I40) -> 0 | K40: 7 | L40: 3 | M40: =SUM(K40:L40)*2 -> 20 | N40: 12 | O40: =O39+N40+M40 -> 150 | P40: =ROUNDDOWN(O40/35,0) -> 4 | Q40: 2 | R40: =IF(V39+Q40>6,V39+Q40-1,V39+Q40) -> 4 | S40: S1+S2 | T40: 4 | U40: 0 | V40: =SUM(R40-T40+U40) -> 0 | W40: =5+S3*2 -> 11 | X40: 3 | Y40: =SUM(W40:X40)*2 -> 28 | Z40: 12 | AA40: =AA39+Z40+Y40 -> 202 | AB40: =ROUNDDOWN(AA40/35,0) -> 5
E41: 2 | F41: =IF(J40+E41>6,J40+E41-1,J40+E41) -> 2 | G41: S1+S3 | H41: 2 | I41: 2 | J41: =SUM(F41-H41+I41) -> 2 | K41: 2 | L41: 3 | M41: =SUM(K41:L41)*2 -> 10 | N41: 6 | O41: =O40+N41+M41 -> 166 | P41: =ROUNDDOWN(O41/35,0) -> 4 | Q41: 2 | R41: =IF(V40+Q41>6,V40+Q41-1,V40+Q41) -> 2 | S41: S1+S3 | T41: 2 | U41: 2 | V41: =SUM(R41-T41+U41) -> 2 | W41: =S3*2 -> 6 | X41: 3 | Y41: =SUM(W41:X41)*2 -> 18 | Z41: 6 | AA41: =AA40+Z41+Y41 -> 226 | AB41: =ROUNDDOWN(AA41/35,0) -> 6
M43: =K35+L35 -> 6
M44: =K36+L36 -> 10
...

Sheet Lewis Conf. Index
A1: Lewis | B1: CI = Confectance Index
A2: Note: S2 casted before toys | E2: V0
A3: Volley | E3: Start turn generation | F3: Current CI | G3: Generated CI from toys | H3: Skill | I3: Cost | J3: Total CI | K3: Total Volley | L3: Total Blaze | M3: Tallied | N3: Ember
E4: 0 | F4: =E4 -> 0 | G4: 2 | H4: S2 | I4: 0 | J4: =G4+F4-I4 -> 2 | K4: 2 | L4: =K4*3 -> 6 | M4: =L4 -> 6 | N4: =ROUNDDOWN(M4/35,0) -> 0
E5: =J4 -> 2 | F5: =E5 -> 2 | G5: 2 | H5: S1 | I5: 0 | J5: =G5+F5-I5 -> 4 | K5: 2 | L5: =K5*3 -> 6 | M5: =M4+L5 -> 12 | N5: =ROUNDDOWN(M5/35,0) -> 0
E6: =J5 -> 4 | F6: =E6 -> 4 | G6: 2 | H6: S3 | I6: 6 | J6: =G6+F6-I6 -> 0 | K6: 4 | L6: =K6*3 -> 12 | M6: =M5+L6 -> 24 | N6: =ROUNDDOWN(M6/35,0) -> 0 | P6: S3 before toy volley
E7: =J6 -> 0 | F7: =E7 -> 0 | G7: 2 | H7: S2 | I7: 0 | J7: =G7+F7-I7 -> 2 | K7: 2 | L7: =K7*3 -> 6 | M7: =M6+L7 -> 30 | N7: =ROUNDDOWN(M7/35,0) -> 0
E8: =J7 -> 2 | F8: =E8 -> 2 | G8: 2 | H8: S1 | I8: 0 | J8: =G8+F8-I8 -> 4 | K8: 2 | L8: =K8*3 -> 6 | M8: =M7+L8 -> 36 | N8: =ROUNDDOWN(M8/35,0) -> 1
E9: =J8 -> 4 | F9: =E9 -> 4 | G9: 2 | H9: S3 | I9: 6 | J9: =G9+F9-I9 -> 0 | K9: 4 | L9: =K9*3 -> 12 | M9: =M8+L9 -> 48 | N9: =ROUNDDOWN(M9/35,0) -> 1 | P9: S3 before toy volley
E10: =J9 -> 0 | F10: =E10 -> 0 | G10: 2 | H10: S2 | I10: 0 | J10: =G10+F10-I10 -> 2 | K10: 2 | L10: =K10*3 -> 6 | M10: =M9+L10 -> 54 | N10: =ROUNDDOWN(M10/35,0) -> 1
A11: Note: at V2 S3 casted before volleys from toys
E12: V2
E13: Start turn generation | F13: Current CI | G13: Generated CI from toys | H13: Skill | I13: Cost | J13: Total CI | K13: Total Volley | L13: Total Blaze | M13: Tallied | N13: Ember
E14: 0 | F14: =E14 -> 0 | G14: 2 | H14: S2 | I14: 0 | J14: =G14+F14-I14 -> 2 | K14: 2 | L14: =K14*3 -> 6 | M14: =L14 -> 6 | N14: =ROUNDDOWN(M14/35,0) -> 0
E15: =J14 -> 2 | F15: =E15 -> 2 | G15: 2 | H15: S1 | I15: 0 | J15: =G15+F15-I15 -> 4 | K15: 4 | L15: =K15*3 -> 12 | M15: =M14+L15 -> 18 | N15: =ROUNDDOWN(M15/35,0) -> 0
E16: =J15 -> 4 | F16: =E16 -> 4 | G16: 2 | H16: S3 | I16: 4 | J16: =G16+F16-I16 -> 2 | K16: 2 | L16: =K16*3 -> 6 | M16: =M15+L16 -> 24 | N16: =ROUNDDOWN(M16/35,0) -> 0 | P16: S3 before toy volley
E17: =J16 -> 2 | F17: =E17 -> 2 | G17: 2 | H17: S3 | I17: 4 | J17: =G17+F17-I17 -> 0 | K17: 4 | L17: =K17*3 -> 12 | M17: =M16+L17 -> 36 | N17: =ROUNDDOWN(M17/35,0) -> 1 | P17: S3 after toy volley
E18: =J17 -> 0 | F18: =E18 -> 0 | G18: 2 | H18: S2 | I18: 0 | J18: =G18+F18-I18 -> 2 | K18: 2 | L18: =K18*3 -> 6 | M18: =M17+L18 -> 42 | N18: =ROUNDDOWN(M18/35,0) -> 1
E19: =J18 -> 2 | F19: =E19 -> 2 | G19: 2 | H19: S3 | I19: 4 | J19: =G19+F19-I19 -> 0 | K19: 4 | L19: =K19*3 -> 12 | M19: =M18+L19 -> 54 | N19: =ROUNDDOWN(M19/35,0) -> 1 | P19: S3 after toy volley
E20: =J19 -> 0 | F20: =E20 -> 0 | G20: 2 | H20: S2 | I20: 0 | J20: =G20+F20-I20 -> 2 | K20: 2 | L20: =K20*3 -> 6 | M20: =M19+L20 -> 60 | N20: =ROUNDDOWN(M20/35,0) -> 1
A21: Note: V6 Assuming Tololo +V2, Niketta +V1, Springfield +V1
E22: V6 | G22: all S3 after volley | K22: Extra actions | L22: =IFERROR('Blaze Calculations'!E5,0) -> 3
E23: Start turn generation | F23: Current CI | G23: Generated CI from toys | H23: Skill | I23: Cost | J23: Total CI | K23: Total Volley | L23: V6 Rank 3 | M23: Total Blaze | N23: Tallied | O23: Ember | S23: volley triggered | T23: blaze count | U23: in screen | V23: Ember
E24: 0 | F24: =E24 -> 0 | G24: 2 | H24: S2 | I24: 0 | J24: =G24+F24-I24 -> 2 | K24: 2 | L24: 0 | M24: =SUM(K24:L24)*3 -> 6 | N24: =M24 -> 6 | O24: =ROUNDDOWN(N24/35,0) -> 0 | R24: Turn 1 | S24: 2 | T24: 6 | U24: 6 | V24: 0
B25: Toy holder with Extra actions | E25: =J24 -> 2 | F25: =E25 -> 2 | G25: 2 | H25: S3 | I25: 4 | J25: =G25+F25-I25 -> 0 | K25: 4 | L25: =$L$22 -> 3 | M25: =SUM(K25:L25)*3 -> 21 | N25: =N24+M25 -> 27 | O25: =ROUNDDOWN(N25/35,0) -> 0 | R25: Turn 2 | S25: =2+(1+1+1+1)+2 -> 8 | T25: =S25*3+T24 -> 30 | U25: 30 | V25: 0
B26: No Extra Action | C26: =IF('Blaze Calculations'!C8="V6",0,"") -> 0 | E26: =J25 -> 0 | F26: =E26 -> 0 | G26: 2 | H26: S2 | I26: 0 | J26: =G26+F26-I26 -> 2 | K26: 2 | L26: =$L$22 -> 3 | M26: =SUM(K26:L26)*3 -> 15 | N26: =N25+M26 -> 42 | O26: =ROUNDDOWN(N26/35,0) -> 1 | P26: =N26-35 -> 7 | R26: Turn 3 | S26: =(1+1)+(1+1+1+1) -> 6 | T26: =S26*3+T25 -> 48 | U26: 13 | V26: 1
B27: +1 Extra Action | C27: =IF('Blaze Calculations'!C8="V6",1,"") -> 1 | E27: =J26 -> 2 | F27: =E27 -> 2 | G27: 2 | H27: S3 | I27: 4 | J27: =G27+F27-I27 -> 0 | K27: 4 | L27: =$L$22 -> 3 | M27: =SUM(K27:L27)*3 -> 21 | N27: =N26+M27 -> 63 | O27: =ROUNDDOWN(N27/35,0) -> 1 | P27: =N27-35-35 -> -7 | R27: Turn 4
B28: +2 Extra Action | C28: =IF('Blaze Calculations'!C8="V6",2,"") -> 2 | E28: =J27 -> 0 | F28: =E28 -> 0 | G28: 2 | H28: S2 | I28: 0 | J28: =G28+F28-I28 -> 2 | K28: 2 | L28: =$L$22 -> 3 | M28: =SUM(K28:L28)*3 -> 15 | N28: =N27+M28 -> 78 | O28: =ROUNDDOWN(N28/35,0) -> 2 | P28: =N28-35-35 -> 8 | R28: Turn 5
E29: =J28 -> 2 | F29: =E29 -> 2 | G29: 2 | H29: S3 | I29: 4 | J29: =G29+F29-I29 -> 0 | K29: 4 | L29: =$L$22 -> 3 | M29: =SUM(K29:L29)*3 -> 21 | N29: =N28+M29 -> 99 | O29: =ROUNDDOWN(N29/35,0) -> 2 | P29: =N29-35-35-35 -> -6 | R29: Turn 6
E30: =J29 -> 0 | F30: =E30 -> 0 | G30: 2 | H30: S2 | I30: 0 | J30: =G30+F30-I30 -> 2 | K30: 2 | L30: =$L$22 -> 3 | M30: =SUM(K30:L30)*3 -> 15 | N30: =N29+M30 -> 114 | O30: =ROUNDDOWN(N30/35,0) -> 3 | P30: =N30-35-35-35 -> 9 | R30: Turn 7
